<?xml version="1.0" ?>
<robot name="cugo"
  xmlns:xacro="http://ros.org/wiki/xacro">

  <link name="base_footprint"/>

  <joint name="base_joint" type="fixed">
    <parent link="base_footprint"/>
    <child link="base_link"/>
    <origin xyz="0.0 0.0 0.010" rpy="0 0 0"/>
  </joint>

  <link name="base_link"/>

  <joint name="wheel_left_joint" type="continuous">
    <parent link="base_link"/>
    <child link="wheel_left_link"/>
    <origin xyz="0.0 0.33 0.0" rpy="0 0 0"/>
    <axis xyz="0 0 1"/>
  </joint>

  <link name="wheel_left_link"/>

  <joint name="wheel_right_joint" type="continuous">
    <parent link="base_link"/>
    <child link="wheel_right_link"/>
    <origin xyz="0.0 -0.33 0.0" rpy="0 0 0"/>
    <axis xyz="0 0 1"/>
  </joint>

  <link name="wheel_right_link"/>

  <joint name="scan_joint" type="fixed">
    <parent link="base_link"/>
    <child link="laser"/>
    <origin xyz="0.0 0 0.2" rpy="0 0 0"/>
  </joint>

  <link name="laser"/>

</robot>
